Workbook

Sheet 9. TURA 30 03 2026
A1: Barcode potrebe | B1: radni nalog | C1: part | D1: materijal | E1: debljina | F1: status | G1: kolica br. | H1: operater | I1: vrijeme | J1: skeniraj QR parta | K1: skeniraj kolica
A2: R4309779 | B2: 025MX003 | C2: Vanjska vrata lijeva | D2: INSB | E2: 0.8 | F2: SAVIJENO | H2: presamarin14@gmail.com | I2: 46113.373
A3: N182718 | B3: 025MX003 | F3: SAVIJENO | H3: presamarin14@gmail.com | I3: 46113.373
A4: N182718 | B4: 025MX003 | F4: IZREZANO | H4: presamarin14@gmail.com | I4: 46113.374
A5: N182720 | B5: 025MX004 | F5: IZREZANO | I5: 46112.906
A6: N182719 | B6: 025MX004 | F6: IZREZANO | I6: 46112.906
A7: R4309780 | B7: 025MX004 | F7: IZREZANO | I7: 46112.906
A8: N182720 | B8: 025MX004 | F8: IZREZANO | I8: 46112.907

Sheet Kopija lista 10. TURA 30 03 202
A1: Barcode potrebe | B1: radni nalog | C1: part | D1: materijal | E1: debljina | F1: status | G1: kolica br. | H1: operater | I1: vrijeme | J1: skeniraj QR parta | K1: skeniraj kolica
A2: ='List 2'!AK5 -> R4092092 | B2: ='List 2'!Y5 -> 195VB001 | C2: ='List 2'!AA5 -> Maska dna_2 | D2: ='List 2'!X5 -> FEZN_2.0MM | E2: 0.8 | F2: SAVIJENO | H2: presamarin14@gmail.com | I2: 46114.585
A3: ='List 2'!AK10 -> R4092093 | B3: ='List 2'!Y10 -> 195VB001 | C3: ='List 2'!AA10 -> Nosac Kola_2 | D3: ='List 2'!X10 -> FEZN_2.0MM | F3: SAVIJENO | H3: presamarin14@gmail.com | I3: 46114.586
A4: ='List 2'!AK6 -> R4092093 | B4: ='List 2'!Y6 -> 195VB001 | C4: ='List 2'!AA6 -> Nosac Kola_2 | D4: ='List 2'!X6 -> FEZN_2.0MM | F4: SAVIJENO | H4: presamarin14@gmail.com | I4: 46114.586
A5: ='List 2'!AK9 -> R4092095 | B5: ='List 2'!Y9 -> 195VB001 | C5: ='List 2'!AA9 -> Ojacanje dna_2 | D5: ='List 2'!X9 -> FEZN_2.0MM | F5: IZREZANO | H5: presamarin14@gmail.com | I5: 46112.906
A6: ='List 2'!AK7 -> R4092095 | B6: ='List 2'!Y7 -> 195VB001 | C6: ='List 2'!AA7 -> Ojacanje dna_2 | D6: ='List 2'!X7 -> FEZN_2.0MM | F6: IZREZANO | H6: presamarin14@gmail.com | I6: 46112.911
A7: ='List 2'!AK8 -> R4092094 | B7: ='List 2'!Y8 -> 195VB001 | C7: ='List 2'!AA8 -> OMEGA DNA_2 | D7: ='List 2'!X8 -> FEZN_2.0MM | F7: IZREZANO | H7: presamarin14@gmail.com | I7: 46113.368
A8: ='List 2'!AK15 -> R4092045 | B8: ='List 2'!Y15 -> 195VB001 | C8: ='List 2'!AA15 -> Bocna strana lijeva | D8: ='List 2'!X15 -> SB_0.8MM | F8: IZREZANO
A9: ='List 2'!AK33 -> R4092045 | B9: ='List 2'!Y33 -> 195VB001 | C9: ='List 2'!AA33 -> Bocna strana lijeva | D9: ='List 2'!X33 -> SB_0.8MM | F9: IZREZANO | H9: presamarin14@gmail.com | I9: 46113.613
A10: ='List 2'!AK21 -> R4092056 | B10: ='List 2'!Y21 -> 195VB001 | C10: ='List 2'!AA21 -> Bocna strana lijeva_sr | D10: ='List 2'!X21 -> SB_0.8MM | F10: IZREZANO
A11: ='List 2'!AK18 -> R4092047 | B11: ='List 2'!Y18 -> 195VB001 | C11: ='List 2'!AA18 -> Bocna stranica desna | D11: ='List 2'!X18 -> SB_0.8MM | F11: IZREZANO
A12: ='List 2'!AK34 -> R4092047 | B12: ='List 2'!Y34 -> 195VB001 | C12: ='List 2'!AA34 -> Bocna stranica desna | D12: ='List 2'!X34 -> SB_0.8MM | F12: IZREZANO
A13: ='List 2'!AK40 -> R4092083 | B13: ='List 2'!Y40 -> 195VB001 | C13: ='List 2'!AA40 -> BOK D_2 | D13: ='List 2'!X40 -> SB_0.8MM | F13: IZREZANO
A14: ='List 2'!AK43 -> R4092084 | B14: ='List 2'!Y43 -> 195VB001 | C14: ='List 2'!AA43 -> BOK L_2 | D14: ='List 2'!X43 -> SB_0.8MM | F14: IZREZANO
A15: ='List 2'!AK11 -> R4092048 | B15: ='List 2'!Y11 -> 195VB001 | C15: ='List 2'!AA11 -> Dno | D15: ='List 2'!X11 -> SB_0.8MM | F15: IZREZANO | H15: presamarin14@gmail.com | I15: 46112.907
A16: ='List 2'!AK17 -> R4092048 | B16: ='List 2'!Y17 -> 195VB001 | C16: ='List 2'!AA17 -> Dno | D16: ='List 2'!X17 -> SB_0.8MM | F16: IZREZANO
A17: ='List 2'!AK29 -> R4092074 | B17: ='List 2'!Y29 -> 195VB001 | C17: ='List 2'!AA29 -> DNO LADICE_2 | D17: ='List 2'!X29 -> SB_0.8MM | F17: IZREZANO
A18: ='List 2'!AK47 -> R4092078 | B18: ='List 2'!Y47 -> 195VB001 | C18: ='List 2'!AA47 -> DNO LADICE_GOR_2 | D18: ='List 2'!X47 -> SB_0.8MM | F18: IZREZANO
A19: ='List 2'!AK41 -> R4092085 | B19: ='List 2'!Y41 -> 195VB001 | C19: ='List 2'!AA41 -> DNO_2 | D19: ='List 2'!X41 -> SB_0.8MM | F19: IZREZANO
A20: ='List 2'!AK16 -> R4092046 | B20: ='List 2'!Y16 -> 195VB001 | C20: ='List 2'!AA16 -> Ledja | D20: ='List 2'!X16 -> SB_0.8MM | F20: IZREZANO | H20: presamarin14@gmail.com | I20: 46112.97 | J20: ='List 2'!AT16
A21: ='List 2'!AK19 -> R4092046 | B21: ='List 2'!Y19 -> 195VB001 | C21: ='List 2'!AA19 -> Ledja | D21: ='List 2'!X19 -> SB_0.8MM | F21: IZREZANO | H21: presamarin14@gmail.com | I21: 46112.97
A22: ='List 2'!AK38 -> R4092086 | B22: ='List 2'!Y38 -> 195VB001 | C22: ='List 2'!AA38 -> LEDJA_2 | D22: ='List 2'!X38 -> SB_0.8MM | F22: IZREZANO
A23: ='List 2'!AK39 -> R4092087 | B23: ='List 2'!Y39 -> 195VB001 | C23: ='List 2'!AA39 -> NOSAC DESNI 1_2 | D23: ='List 2'!X39 -> SB_0.8MM | F23: IZREZANO
A24: ='List 2'!AK52 -> R4092088 | B24: ='List 2'!Y52 -> 195VB001 | C24: ='List 2'!AA52 -> NOSAC DESNI STRZ_2 | D24: ='List 2'!X52 -> SB_0.8MM | F24: IZREZANO
A25: ='List 2'!AK20 -> R4092089 | B25: ='List 2'!Y20 -> 195VB001 | C25: ='List 2'!AA20 -> NOSAC LIJEVI 1_2 | D25: ='List 2'!X20 -> SB_0.8MM | F25: IZREZANO
A26: ='List 2'!AK45 -> R4092090 | B26: ='List 2'!Y45 -> 195VB001 | C26: ='List 2'!AA45 -> NOSAC LIJEVI STRZ_2 | D26: ='List 2'!X45 -> SB_0.8MM | F26: IZREZANO
A27: ='List 2'!AK55 -> R4092052 | B27: ='List 2'!Y55 -> 195VB001 | C27: ='List 2'!AA55 -> Nosac police 1 | D27: ='List 2'!X55 -> SB_0.8MM | F27: IZREZANO
A28: ='List 2'!AK58 -> R4092052 | B28: ='List 2'!Y58 -> 195VB001 | C28: ='List 2'!AA58 -> Nosac police 1 | D28: ='List 2'!X58 -> SB_0.8MM | F28: IZREZANO
A29: ='List 2'!AK12 -> R4092057 | B29: ='List 2'!Y12 -> 195VB001 | C29: ='List 2'!AA12 -> Nosac police 1_sr | D29: ='List 2'!X12 -> SB_0.8MM | F29: IZREZANO
A30: ='List 2'!AK56 -> R4092053 | B30: ='List 2'!Y56 -> 195VB001 | C30: ='List 2'!AA56 -> Nosac police 2 | D30: ='List 2'!X56 -> SB_0.8MM | F30: IZREZANO
A31: ='List 2'!AK57 -> R4092053 | B31: ='List 2'!Y57 -> 195VB001 | C31: ='List 2'!AA57 -> Nosac police 2 | D31: ='List 2'!X57 -> SB_0.8MM | F31: IZREZANO
A32: ='List 2'!AK22 -> R4092050 | B32: ='List 2'!Y22 -> 195VB001 | C32: ='List 2'!AA22 -> Omega dna A | D32: ='List 2'!X22 -> SB_0.8MM | F32: IZREZANO
A33: ='List 2'!AK53 -> R4092050 | B33: ='List 2'!Y53 -> 195VB001 | C33: ='List 2'!AA53 -> Omega dna A | D33: ='List 2'!X53 -> SB_0.8MM | F33: IZREZANO
A34: ='List 2'!AK27 -> R4092051 | B34: ='List 2'!Y27 -> 195VB001 | C34: ='List 2'!AA27 -> Omega dna B | D34: ='List 2'!X27 -> SB_0.8MM | F34: IZREZANO
A35: ='List 2'!AK54 -> R4092051 | B35: ='List 2'!Y54 -> 195VB001 | C35: ='List 2'!AA54 -> Omega dna B | D35: ='List 2'!X54 -> SB_0.8MM | F35: IZREZANO
A36: ='List 2'!AK14 -> R4092055 | B36: ='List 2'!Y14 -> 195VB001 | C36: ='List 2'!AA14 -> Omega police | D36: ='List 2'!X14 -> SB_0.8MM | F36: IZREZANO
A37: ='List 2'!AK37 -> R4092055 | B37: ='List 2'!Y37 -> 195VB001 | C37: ='List 2'!AA37 -> Omega police | D37: ='List 2'!X37 -> SB_0.8MM | F37: IZREZANO
A38: ='List 2'!AK13 -> R4092075 | B38: ='List 2'!Y13 -> 195VB001 | C38: ='List 2'!AA13 -> PLAST LADICE_2 | D38: ='List 2'!X13 -> SB_0.8MM | F38: IZREZANO
A39: ='List 2'!AK36 -> R4092079 | B39: ='List 2'!Y36 -> 195VB001 | C39: ='List 2'!AA36 -> PLAST LADICE_GOR_2 | D39: ='List 2'!X36 -> SB_0.8MM | F39: IZREZANO
A40: ='List 2'!AK23 -> R4092049 | B40: ='List 2'!Y23 -> 195VB001 | C40: ='List 2'!AA23 -> Poklopnica | D40: ='List 2'!X23 -> SB_0.8MM | F40: IZREZANO
...

Sheet Kopija lista Kopija lista 10. T
A1: Barcode potrebe | B1: radni nalog | C1: part | D1: materijal | E1: debljina | F1: status | G1: kolica br. | H1: operater | I1: vrijeme | J1: skeniraj QR parta | K1: skeniraj kolica | L1: 15
A2: ='List 2'!AK5 -> R4092092 | B2: ='List 2'!Y5 -> 195VB001 | C2: ='List 2'!AA5 -> Maska dna_2 | D2: ='List 2'!X5 -> FEZN_2.0MM | E2: 0.8 | F2: IZREZANO
A3: ='List 2'!AK10 -> R4092093 | B3: ='List 2'!Y10 -> 195VB001 | C3: ='List 2'!AA10 -> Nosac Kola_2 | D3: ='List 2'!X10 -> FEZN_2.0MM | F3: IZREZANO
A4: ='List 2'!AK6 -> R4092093 | B4: ='List 2'!Y6 -> 195VB001 | C4: ='List 2'!AA6 -> Nosac Kola_2 | D4: ='List 2'!X6 -> FEZN_2.0MM | F4: IZREZANO
A5: ='List 2'!AK9 -> R4092095 | B5: ='List 2'!Y9 -> 195VB001 | C5: ='List 2'!AA9 -> Ojacanje dna_2 | D5: ='List 2'!X9 -> FEZN_2.0MM | F5: IZREZANO
A6: ='List 2'!AK7 -> R4092095 | B6: ='List 2'!Y7 -> 195VB001 | C6: ='List 2'!AA7 -> Ojacanje dna_2 | D6: ='List 2'!X7 -> FEZN_2.0MM | F6: IZREZANO
A7: ='List 2'!AK8 -> R4092094 | B7: ='List 2'!Y8 -> 195VB001 | C7: ='List 2'!AA8 -> OMEGA DNA_2 | D7: ='List 2'!X8 -> FEZN_2.0MM | F7: IZREZANO
A8: ='List 2'!AK15 -> R4092045 | B8: ='List 2'!Y15 -> 195VB001 | C8: ='List 2'!AA15 -> Bocna strana lijeva | D8: ='List 2'!X15 -> SB_0.8MM | F8: IZREZANO
A9: ='List 2'!AK33 -> R4092045 | B9: ='List 2'!Y33 -> 195VB001 | C9: ='List 2'!AA33 -> Bocna strana lijeva | D9: ='List 2'!X33 -> SB_0.8MM | F9: IZREZANO
A10: ='List 2'!AK21 -> R4092056 | B10: ='List 2'!Y21 -> 195VB001 | C10: ='List 2'!AA21 -> Bocna strana lijeva_sr | D10: ='List 2'!X21 -> SB_0.8MM | F10: IZREZANO
A11: ='List 2'!AK18 -> R4092047 | B11: ='List 2'!Y18 -> 195VB001 | C11: ='List 2'!AA18 -> Bocna stranica desna | D11: ='List 2'!X18 -> SB_0.8MM | F11: IZREZANO
A12: ='List 2'!AK34 -> R4092047 | B12: ='List 2'!Y34 -> 195VB001 | C12: ='List 2'!AA34 -> Bocna stranica desna | D12: ='List 2'!X34 -> SB_0.8MM | F12: IZREZANO
A13: ='List 2'!AK40 -> R4092083 | B13: ='List 2'!Y40 -> 195VB001 | C13: ='List 2'!AA40 -> BOK D_2 | D13: ='List 2'!X40 -> SB_0.8MM | F13: IZREZANO
A14: ='List 2'!AK43 -> R4092084 | B14: ='List 2'!Y43 -> 195VB001 | C14: ='List 2'!AA43 -> BOK L_2 | D14: ='List 2'!X43 -> SB_0.8MM | F14: IZREZANO
A15: ='List 2'!AK11 -> R4092048 | B15: ='List 2'!Y11 -> 195VB001 | C15: ='List 2'!AA11 -> Dno | D15: ='List 2'!X11 -> SB_0.8MM | F15: IZREZANO
A16: ='List 2'!AK17 -> R4092048 | B16: ='List 2'!Y17 -> 195VB001 | C16: ='List 2'!AA17 -> Dno | D16: ='List 2'!X17 -> SB_0.8MM | F16: IZREZANO
A17: ='List 2'!AK29 -> R4092074 | B17: ='List 2'!Y29 -> 195VB001 | C17: ='List 2'!AA29 -> DNO LADICE_2 | D17: ='List 2'!X29 -> SB_0.8MM | F17: IZREZANO
A18: ='List 2'!AK47 -> R4092078 | B18: ='List 2'!Y47 -> 195VB001 | C18: ='List 2'!AA47 -> DNO LADICE_GOR_2 | D18: ='List 2'!X47 -> SB_0.8MM | F18: IZREZANO
A19: ='List 2'!AK41 -> R4092085 | B19: ='List 2'!Y41 -> 195VB001 | C19: ='List 2'!AA41 -> DNO_2 | D19: ='List 2'!X41 -> SB_0.8MM | F19: IZREZANO
A20: ='List 2'!AK16 -> R4092046 | B20: ='List 2'!Y16 -> 195VB001 | C20: ='List 2'!AA16 -> Ledja | D20: ='List 2'!X16 -> SB_0.8MM | F20: IZREZANO | J20: ='List 2'!AT16
A21: ='List 2'!AK19 -> R4092046 | B21: ='List 2'!Y19 -> 195VB001 | C21: ='List 2'!AA19 -> Ledja | D21: ='List 2'!X19 -> SB_0.8MM | F21: IZREZANO
A22: ='List 2'!AK38 -> R4092086 | B22: ='List 2'!Y38 -> 195VB001 | C22: ='List 2'!AA38 -> LEDJA_2 | D22: ='List 2'!X38 -> SB_0.8MM | F22: IZREZANO
A23: ='List 2'!AK39 -> R4092087 | B23: ='List 2'!Y39 -> 195VB001 | C23: ='List 2'!AA39 -> NOSAC DESNI 1_2 | D23: ='List 2'!X39 -> SB_0.8MM | F23: IZREZANO
A24: ='List 2'!AK52 -> R4092088 | B24: ='List 2'!Y52 -> 195VB001 | C24: ='List 2'!AA52 -> NOSAC DESNI STRZ_2 | D24: ='List 2'!X52 -> SB_0.8MM | F24: IZREZANO
A25: ='List 2'!AK20 -> R4092089 | B25: ='List 2'!Y20 -> 195VB001 | C25: ='List 2'!AA20 -> NOSAC LIJEVI 1_2 | D25: ='List 2'!X20 -> SB_0.8MM | F25: IZREZANO
A26: ='List 2'!AK45 -> R4092090 | B26: ='List 2'!Y45 -> 195VB001 | C26: ='List 2'!AA45 -> NOSAC LIJEVI STRZ_2 | D26: ='List 2'!X45 -> SB_0.8MM | F26: IZREZANO
A27: ='List 2'!AK55 -> R4092052 | B27: ='List 2'!Y55 -> 195VB001 | C27: ='List 2'!AA55 -> Nosac police 1 | D27: ='List 2'!X55 -> SB_0.8MM | F27: IZREZANO
A28: ='List 2'!AK58 -> R4092052 | B28: ='List 2'!Y58 -> 195VB001 | C28: ='List 2'!AA58 -> Nosac police 1 | D28: ='List 2'!X58 -> SB_0.8MM | F28: IZREZANO
A29: ='List 2'!AK12 -> R4092057 | B29: ='List 2'!Y12 -> 195VB001 | C29: ='List 2'!AA12 -> Nosac police 1_sr | D29: ='List 2'!X12 -> SB_0.8MM | F29: IZREZANO
A30: ='List 2'!AK56 -> R4092053 | B30: ='List 2'!Y56 -> 195VB001 | C30: ='List 2'!AA56 -> Nosac police 2 | D30: ='List 2'!X56 -> SB_0.8MM | F30: IZREZANO
A31: ='List 2'!AK57 -> R4092053 | B31: ='List 2'!Y57 -> 195VB001 | C31: ='List 2'!AA57 -> Nosac police 2 | D31: ='List 2'!X57 -> SB_0.8MM | F31: IZREZANO
A32: ='List 2'!AK22 -> R4092050 | B32: ='List 2'!Y22 -> 195VB001 | C32: ='List 2'!AA22 -> Omega dna A | D32: ='List 2'!X22 -> SB_0.8MM | F32: IZREZANO
A33: ='List 2'!AK53 -> R4092050 | B33: ='List 2'!Y53 -> 195VB001 | C33: ='List 2'!AA53 -> Omega dna A | D33: ='List 2'!X53 -> SB_0.8MM | F33: IZREZANO
A34: ='List 2'!AK27 -> R4092051 | B34: ='List 2'!Y27 -> 195VB001 | C34: ='List 2'!AA27 -> Omega dna B | D34: ='List 2'!X27 -> SB_0.8MM | F34: IZREZANO
A35: ='List 2'!AK54 -> R4092051 | B35: ='List 2'!Y54 -> 195VB001 | C35: ='List 2'!AA54 -> Omega dna B | D35: ='List 2'!X54 -> SB_0.8MM | F35: IZREZANO
A36: ='List 2'!AK14 -> R4092055 | B36: ='List 2'!Y14 -> 195VB001 | C36: ='List 2'!AA14 -> Omega police | D36: ='List 2'!X14 -> SB_0.8MM | F36: IZREZANO
A37: ='List 2'!AK37 -> R4092055 | B37: ='List 2'!Y37 -> 195VB001 | C37: ='List 2'!AA37 -> Omega police | D37: ='List 2'!X37 -> SB_0.8MM | F37: IZREZANO
A38: ='List 2'!AK13 -> R4092075 | B38: ='List 2'!Y13 -> 195VB001 | C38: ='List 2'!AA13 -> PLAST LADICE_2 | D38: ='List 2'!X13 -> SB_0.8MM | F38: IZREZANO
A39: ='List 2'!AK36 -> R4092079 | B39: ='List 2'!Y36 -> 195VB001 | C39: ='List 2'!AA36 -> PLAST LADICE_GOR_2 | D39: ='List 2'!X36 -> SB_0.8MM | F39: IZREZANO
A40: ='List 2'!AK23 -> R4092049 | B40: ='List 2'!Y23 -> 195VB001 | C40: ='List 2'!AA23 -> Poklopnica | D40: ='List 2'!X23 -> SB_0.8MM | F40: IZREZANO
...

Sheet List 2
D4: FileName | E4: REPORTNUM | F4: REPORTLOGO | G4: JOBNAME | H4: MACHINE | I4: OPERATORCOMMENT | J4: NESTINGJPG | K4: SHEETNAME | L4: SHEETDIMX | M4: SHEETDIMY | N4: MATERIAL | O4: THICKNESS | P4: CUTTIME | Q4: SCRAPTIME | R4: NOTUSE | S4: WEIGTH | T4: USE | U4: INSTANCES | V4: SHEETDESCRIPTION | W4: ID | X4: DXF | Y4: NALOG | Z4: DISKRIMINANTA | AA4: PART | AB4: BENDS | AC4: BROJ | AD4: BROJ MAX | AE4: QUANTITY | AF4: DRAWING | AG4: CUTTIME2 | AH4: WEIGTH3 | AI4: DESCRIPTION | AJ4: opc_barkoda_rn | AK4: opc_barkod_potrebe | AL4: opc_naziv_partner_potreba | AM4: dn_sifraid | AN4: dn_nazivid | AO4: opc_dnopomba | AP4: Prebrojavanje | AQ4: IconNumber | AR4: Path | AS4: Datum | AT4: PR_NALJ
D5: 16062025fezn2_0mmReportTemplate.xml | E5: 55 | F5: C:\PrimaIndustrie\Maestro\Config\Resources\prima_power [320x200].png | G5: 16062025fezn2_0mmReport | H5: PLTHS1530_YLS3000 | J5: C:\NTCam\data\Reports\Resources\Nestings\16062025fezn2_0mm_SHT9_1.png | K5: SH1.ISO | L5: 2500(2473,468) | M5: 1250(1242) | N5: FEZN_GALV_AIR | O5: 2 | P5: 0.00:00:10 | Q5: 1 | R5: 83383 | S5: 49063 | T5: 40910 | U5: 1 | W5: 3 | X5: FEZN_2.0MM | Y5: 195VB001 | Z5: A | AA5: Maska dna_2 | AB5: BENDS4 | AC5: 1 | AD5: 1 | AE5: 1 | AF5: 3 | AG5: 0.00:00:00 | AH5: 876 | AJ5: N169535 | AK5: R4092092 | AL5: VOX-BRANKO | AM5: 6161 | AN5: ORMAR INOX | AP5: 1 od 78 | AQ5: 9 | AR5: Z:\005_Proizvodnja\004_Organizacija\Ledinski obrada TURA\PNG IKONE\9.png | AS5: 46112
D6: 16062025fezn2_0mmReportTemplate.xml | E6: 55 | F6: C:\PrimaIndustrie\Maestro\Config\Resources\prima_power [320x200].png | G6: 16062025fezn2_0mmReport | H6: PLTHS1530_YLS3000 | J6: C:\NTCam\data\Reports\Resources\Nestings\16062025fezn2_0mm_SHT9_2.png | K6: SH2.ISO | L6: 2500(2492) | M6: 1250(1242) | N6: FEZN_GALV_AIR | O6: 2 | P6: 0.00:00:10 | Q6: 1 | R6: 82047 | S6: 49063 | T6: 40254 | U6: 1 | W6: 22 | X6: FEZN_2.0MM | Y6: 195VB001 | Z6: A | AA6: Nosac Kola_2 | AB6: BENDS4 | AC6: 1 | AD6: 2 | AE6: 1 | AF6: 14 | AG6: 0.00:00:00 | AH6: 1289 | AJ6: N169535 | AK6: R4092093 | AL6: VOX-BRANKO | AM6: 6161 | AN6: ORMAR INOX | AP6: 2 od 78 | AQ6: 9 | AR6: Z:\005_Proizvodnja\004_Organizacija\Ledinski obrada TURA\PNG IKONE\9.png | AS6: 46112
D7: 16062025fezn2_0mmReportTemplate.xml | E7: 55 | F7: C:\PrimaIndustrie\Maestro\Config\Resources\prima_power [320x200].png | G7: 16062025fezn2_0mmReport | H7: PLTHS1530_YLS3000 | J7: C:\NTCam\data\Reports\Resources\Nestings\16062025fezn2_0mm_SHT9_2.png | K7: SH2.ISO | L7: 2500(2492) | M7: 1250(1242) | N7: FEZN_GALV_AIR | O7: 2 | P7: 0.00:00:10 | Q7: 1 | R7: 82047 | S7: 49063 | T7: 40254 | U7: 1 | W7: 34 | X7: FEZN_2.0MM | Y7: 195VB001 | Z7: A | AA7: Ojacanje dna_2 | AB7: BENDS4 | AC7: 2 | AD7: 2 | AE7: 1 | AF7: 13 | AG7: 0.00:00:00 | AH7: 1266 | AJ7: N169535 | AK7: R4092095 | AL7: VOX-BRANKO | AM7: 6161 | AN7: ORMAR INOX | AP7: 5 od 78 | AQ7: 9 | AR7: Z:\005_Proizvodnja\004_Organizacija\Ledinski obrada TURA\PNG IKONE\9.png | AS7: 46112
D8: 16062025fezn2_0mmReportTemplate.xml | E8: 55 | F8: C:\PrimaIndustrie\Maestro\Config\Resources\prima_power [320x200].png | G8: 16062025fezn2_0mmReport | H8: PLTHS1530_YLS3000 | J8: C:\NTCam\data\Reports\Resources\Nestings\16062025fezn2_0mm_SHT9_2.png | K8: SH2.ISO | L8: 2500(2492) | M8: 1250(1242) | N8: FEZN_GALV_AIR | O8: 2 | P8: 0.00:00:10 | Q8: 1 | R8: 82047 | S8: 49063 | T8: 40254 | U8: 1 | W8: 35 | X8: FEZN_2.0MM | Y8: 195VB001 | Z8: A | AA8: OMEGA DNA_2 | AB8: BENDS4 | AC8: 1 | AD8: 1 | AE8: 1 | AF8: 3 | AG8: 0.00:00:00 | AH8: 1119 | AJ8: N169535 | AK8: R4092094 | AL8: VOX-BRANKO | AM8: 6161 | AN8: ORMAR INOX | AP8: 6 od 78 | AQ8: 9 | AR8: Z:\005_Proizvodnja\004_Organizacija\Ledinski obrada TURA\PNG IKONE\9.png | AS8: 46112
D9: 16062025fezn2_0mmReportTemplate.xml | E9: 55 | F9: C:\PrimaIndustrie\Maestro\Config\Resources\prima_power [320x200].png | G9: 16062025fezn2_0mmReport | H9: PLTHS1530_YLS3000 | J9: C:\NTCam\data\Reports\Resources\Nestings\16062025fezn2_0mm_SHT9_2.png | K9: SH2.ISO | L9: 2500(2492) | M9: 1250(1242) | N9: FEZN_GALV_AIR | O9: 2 | P9: 0.00:00:10 | Q9: 1 | R9: 82047 | S9: 49063 | T9: 40254 | U9: 1 | W9: 42 | X9: FEZN_2.0MM | Y9: 195VB001 | Z9: A | AA9: Ojacanje dna_2 | AB9: BENDS4 | AC9: 1 | AD9: 2 | AE9: 1 | AF9: 13 | AG9: 0.00:00:00 | AH9: 1266 | AJ9: N169535 | AK9: R4092095 | AL9: VOX-BRANKO | AM9: 6161 | AN9: ORMAR INOX | AP9: 9 od 78 | AQ9: 9 | AR9: Z:\005_Proizvodnja\004_Organizacija\Ledinski obrada TURA\PNG IKONE\9.png | AS9: 46112
D10: 16062025fezn2_0mmReportTemplate.xml | E10: 55 | F10: C:\PrimaIndustrie\Maestro\Config\Resources\prima_power [320x200].png | G10: 16062025fezn2_0mmReport | H10: PLTHS1530_YLS3000 | J10: C:\NTCam\data\Reports\Resources\Nestings\16062025fezn2_0mm_SHT9_2.png | K10: SH2.ISO | L10: 2500(2492) | M10: 1250(1242) | N10: FEZN_GALV_AIR | O10: 2 | P10: 0.00:00:10 | Q10: 1 | R10: 82047 | S10: 49063 | T10: 40254 | U10: 1 | W10: 44 | X10: FEZN_2.0MM | Y10: 195VB001 | Z10: A | AA10: Nosac Kola_2 | AB10: BENDS4 | AC10: 2 | AD10: 2 | AE10: 1 | AF10: 14 | AG10: 0.00:00:00 | AH10: 1289 | AJ10: N169535 | AK10: R4092093 | AL10: VOX-BRANKO | AM10: 6161 | AN10: ORMAR INOX | AP10: 11 od 78 | AQ10: 9 | AR10: Z:\005_Proizvodnja\004_Organizacija\Ledinski obrada TURA\PNG IKONE\9.png | AS10: 46112
D11: 16062025sb0_8mmReportTemplate.xml | E11: 55 | F11: C:\PrimaIndustrie\Maestro\Config\Resources\prima_power [320x200].png | G11: 16062025sb0_8mmReport | H11: PLTHS1530_YLS3000 | J11: C:\NTCam\data\Reports\Resources\Nestings\16062025sb0_8mm_SHT2_1.png | K11: SH1.ISO | L11: 3000(2992) | M11: 1500(1492) | N11: INOX_FILM_AIR | O11: 8 | P11: 0.00:00:01 | Q11: 1 | R11: 94197 | S11: 28260 | T11: 26620 | U11: 1 | W11: 3 | X11: SB_0.8MM | Y11: 195VB001 | Z11: C | AA11: Dno | AB11: BENDS4 | AC11: 1 | AD11: 1 | AE11: 1 | AF11: 1 | AG11: 0.00:00:00 | AH11: 4443 | AI11: Multi Import Dxf | AJ11: N169535 | AK11: R4092048 | AL11: VOX-BRANKO | AM11: 6161 | AN11: ORMAR INOX | AP11: 13 od 78 | AQ11: 9 | AR11: Z:\005_Proizvodnja\004_Organizacija\Ledinski obrada TURA\PNG IKONE\9.png | AS11: 46112
D12: 16062025sb0_8mmReportTemplate.xml | E12: 55 | F12: C:\PrimaIndustrie\Maestro\Config\Resources\prima_power [320x200].png | G12: 16062025sb0_8mmReport | H12: PLTHS1530_YLS3000 | J12: C:\NTCam\data\Reports\Resources\Nestings\16062025sb0_8mm_SHT2_1.png | K12: SH1.ISO | L12: 3000(2992) | M12: 1500(1492) | N12: INOX_FILM_AIR | O12: 8 | P12: 0.00:00:01 | Q12: 1 | R12: 94197 | S12: 28260 | T12: 26620 | U12: 1 | W12: 4 | X12: SB_0.8MM | Y12: 195VB001 | Z12: B | AA12: Nosac police 1_sr | AB12: BENDS4 | AC12: 1 | AD12: 1 | AE12: 1 | AF12: 18 | AG12: 0.00:00:00 | AH12: 686 | AI12: Multi Import Dxf | AJ12: N169535 | AK12: R4092057 | AL12: VOX-BRANKO | AM12: 6161 | AN12: ORMAR INOX | AP12: 14 od 78 | AQ12: 9 | AR12: Z:\005_Proizvodnja\004_Organizacija\Ledinski obrada TURA\PNG IKONE\9.png | AS12: 46112
D13: 16062025sb0_8mmReportTemplate.xml | E13: 55 | F13: C:\PrimaIndustrie\Maestro\Config\Resources\prima_power [320x200].png | G13: 16062025sb0_8mmReport | H13: PLTHS1530_YLS3000 | J13: C:\NTCam\data\Reports\Resources\Nestings\16062025sb0_8mm_SHT2_2.png | K13: SH2.ISO | L13: 3000(2918,091) | M13: 1500(1492) | N13: INOX_FILM_AIR | O13: 8 | P13: 0.00:00:01 | Q13: 1 | R13: 91173 | S13: 28260 | T13: 25766 | U13: 1 | W13: 9 | X13: SB_0.8MM | Y13: 195VB001 | Z13: A | AA13: PLAST LADICE_2 | AB13: BENDS4 | AC13: 1 | AD13: 1 | AE13: 1 | AF13: 5 | AG13: 0.00:00:00 | AH13: 4371 | AI13: Multi Import Dxf | AJ13: N169535 | AK13: R4092075 | AL13: VOX-BRANKO | AM13: 6161 | AN13: ORMAR INOX | AP13: 15 od 78 | AQ13: 9 | AR13: Z:\005_Proizvodnja\004_Organizacija\Ledinski obrada TURA\PNG IKONE\9.png | AS13: 46112
D14: 16062025sb0_8mmReportTemplate.xml | E14: 55 | F14: C:\PrimaIndustrie\Maestro\Config\Resources\prima_power [320x200].png | G14: 16062025sb0_8mmReport | H14: PLTHS1530_YLS3000 | J14: C:\NTCam\data\Reports\Resources\Nestings\16062025sb0_8mm_SHT2_2.png | K14: SH2.ISO | L14: 3000(2918,091) | M14: 1500(1492) | N14: INOX_FILM_AIR | O14: 8 | P14: 0.00:00:01 | Q14: 1 | R14: 91173 | S14: 28260 | T14: 25766 | U14: 1 | W14: 11 | X14: SB_0.8MM | Y14: 195VB001 | Z14: B | AA14: Omega police | AB14: BENDS4 | AC14: 1 | AD14: 2 | AE14: 1 | AF14: 1 | AG14: 0.00:00:00 | AH14: 467 | AI14: Multi Import Dxf | AJ14: N169535 | AK14: R4092055 | AL14: VOX-BRANKO | AM14: 6161 | AN14: ORMAR INOX | AP14: 16 od 78 | AQ14: 9 | AR14: Z:\005_Proizvodnja\004_Organizacija\Ledinski obrada TURA\PNG IKONE\9.png | AS14: 46112
D15: 16062025sb0_8mmReportTemplate.xml | E15: 55 | F15: C:\PrimaIndustrie\Maestro\Config\Resources\prima_power [320x200].png | G15: 16062025sb0_8mmReport | H15: PLTHS1530_YLS3000 | J15: C:\NTCam\data\Reports\Resources\Nestings\16062025sb0_8mm_SHT2_3.png | K15: SH3.ISO | L15: 3000(2990,982) | M15: 1500(1492) | N15: INOX_FILM_AIR | O15: 8 | P15: 0.00:00:01 | Q15: 1 | R15: 92895 | S15: 28260 | T15: 26252 | U15: 1 | W15: 14 | X15: SB_0.8MM | Y15: 195VB001 | Z15: B | AA15: Bocna strana lijeva | AB15: BENDS4 | AC15: 1 | AD15: 1 | AE15: 1 | AF15: 1 | AG15: 0.00:00:00 | AH15: 5976 | AI15: Multi Import Dxf | AJ15: N169535 | AK15: R4092045 | AL15: VOX-BRANKO | AM15: 6161 | AN15: ORMAR INOX | AP15: 17 od 78 | AQ15: 9 | AR15: Z:\005_Proizvodnja\004_Organizacija\Ledinski obrada TURA\PNG IKONE\9.png | AS15: 46112
D16: 16062025sb0_8mmReportTemplate.xml | E16: 55 | F16: C:\PrimaIndustrie\Maestro\Config\Resources\prima_power [320x200].png | G16: 16062025sb0_8mmReport | H16: PLTHS1530_YLS3000 | J16: C:\NTCam\data\Reports\Resources\Nestings\16062025sb0_8mm_SHT2_4.png | K16: SH4.ISO | L16: 3000(2992) | M16: 1500(1492) | N16: INOX_FILM_AIR | O16: 8 | P16: 0.00:00:01 | Q16: 1 | R16: 92807 | S16: 28260 | T16: 26227 | U16: 1 | W16: 18 | X16: SB_0.8MM | Y16: 195VB001 | Z16: B | AA16: Ledja | AB16: BENDS4 | AC16: 1 | AD16: 1 | AE16: 1 | AF16: 38 | AG16: 0.00:00:00 | AH16: 7597 | AI16: Multi Import Dxf | AJ16: N169535 | AK16: R4092046 | AL16: VOX-BRANKO | AM16: 6161 | AN16: ORMAR INOX | AP16: 19 od 78 | AQ16: 9 | AR16: Z:\005_Proizvodnja\004_Organizacija\Ledinski obrada TURA\PNG IKONE\9.png | AS16: 46112
D17: 16062025sb0_8mmReportTemplate.xml | E17: 55 | F17: C:\PrimaIndustrie\Maestro\Config\Resources\prima_power [320x200].png | G17: 16062025sb0_8mmReport | H17: PLTHS1530_YLS3000 | J17: C:\NTCam\data\Reports\Resources\Nestings\16062025sb0_8mm_SHT2_5.png | K17: SH5.ISO | L17: 3000(2964,801) | M17: 1500(1492) | N17: INOX_FILM_AIR | O17: 8 | P17: 0.00:00:01 | Q17: 1 | R17: 92890 | S17: 28260 | T17: 26251 | U17: 1 | W17: 27 | X17: SB_0.8MM | Y17: 195VB001 | Z17: B | AA17: Dno | AB17: BENDS4 | AC17: 1 | AD17: 1 | AE17: 1 | AF17: 1 | AG17: 0.00:00:00 | AH17: 5808 | AI17: Multi Import Dxf | AJ17: N169535 | AK17: R4092048 | AL17: VOX-BRANKO | AM17: 6161 | AN17: ORMAR INOX | AP17: 21 od 78 | AQ17: 9 | AR17: Z:\005_Proizvodnja\004_Organizacija\Ledinski obrada TURA\PNG IKONE\9.png | AS17: 46112
D18: 16062025sb0_8mmReportTemplate.xml | E18: 55 | F18: C:\PrimaIndustrie\Maestro\Config\Resources\prima_power [320x200].png | G18: 16062025sb0_8mmReport | H18: PLTHS1530_YLS3000 | J18: C:\NTCam\data\Reports\Resources\Nestings\16062025sb0_8mm_SHT2_6.png | K18: SH6.ISO | L18: 3000(2992) | M18: 1500(1488,446) | N18: INOX_FILM_AIR | O18: 8 | P18: 0.00:00:01 | Q18: 1 | R18: 92275 | S18: 28260 | T18: 26077 | U18: 1 | W18: 32 | X18: SB_0.8MM | Y18: 195VB001 | Z18: B | AA18: Bocna stranica desna | AB18: BENDS4 | AC18: 1 | AD18: 1 | AE18: 1 | AF18: 1 | AG18: 0.00:00:00 | AH18: 5976 | AI18: Multi Import Dxf | AJ18: N169535 | AK18: R4092047 | AL18: VOX-BRANKO | AM18: 6161 | AN18: ORMAR INOX | AP18: 22 od 78 | AQ18: 9 | AR18: Z:\005_Proizvodnja\004_Organizacija\Ledinski obrada TURA\PNG IKONE\9.png | AS18: 46112
D19: 16062025sb0_8mmReportTemplate.xml | E19: 55 | F19: C:\PrimaIndustrie\Maestro\Config\Resources\prima_power [320x200].png | G19: 16062025sb0_8mmReport | H19: PLTHS1530_YLS3000 | J19: C:\NTCam\data\Reports\Resources\Nestings\16062025sb0_8mm_SHT2_6.png | K19: SH6.ISO | L19: 3000(2992) | M19: 1500(1488,446) | N19: INOX_FILM_AIR | O19: 8 | P19: 0.00:00:01 | Q19: 1 | R19: 92275 | S19: 28260 | T19: 26077 | U19: 1 | W19: 36 | X19: SB_0.8MM | Y19: 195VB001 | Z19: C | AA19: Ledja | AB19: BENDS4 | AC19: 1 | AD19: 1 | AE19: 1 | AF19: 13 | AG19: 0.00:00:00 | AH19: 8093 | AI19: Multi Import Dxf | AJ19: N169535 | AK19: R4092046 | AL19: VOX-BRANKO | AM19: 6161 | AN19: ORMAR INOX | AP19: 23 od 78 | AQ19: 9 | AR19: Z:\005_Proizvodnja\004_Organizacija\Ledinski obrada TURA\PNG IKONE\9.png | AS19: 46112
D20: 16062025sb0_8mmReportTemplate.xml | E20: 55 | F20: C:\PrimaIndustrie\Maestro\Config\Resources\prima_power [320x200].png | G20: 16062025sb0_8mmReport | H20: PLTHS1530_YLS3000 | J20: C:\NTCam\data\Reports\Resources\Nestings\16062025sb0_8mm_SHT2_8.png | K20: SH8.ISO | L20: 3000(2992) | M20: 1500(1492) | N20: INOX_FILM_AIR | O20: 8 | P20: 0.00:00:01 | Q20: 1 | R20: 92780 | S20: 28260 | T20: 26220 | U20: 1 | W20: 50 | X20: SB_0.8MM | Y20: 195VB001 | Z20: A | AA20: NOSAC LIJEVI 1_2 | AB20: BENDS4 | AC20: 1 | AD20: 1 | AE20: 1 | AF20: 4 | AG20: 0.00:00:00 | AH20: 471 | AI20: Multi Import Dxf | AJ20: N169535 | AK20: R4092089 | AL20: VOX-BRANKO | AM20: 6161 | AN20: ORMAR INOX | AP20: 24 od 78 | AQ20: 9 | AR20: Z:\005_Proizvodnja\004_Organizacija\Ledinski obrada TURA\PNG IKONE\9.png | AS20: 46112
D21: 16062025sb0_8mmReportTemplate.xml | E21: 55 | F21: C:\PrimaIndustrie\Maestro\Config\Resources\prima_power [320x200].png | G21: 16062025sb0_8mmReport | H21: PLTHS1530_YLS3000 | J21: C:\NTCam\data\Reports\Resources\Nestings\16062025sb0_8mm_SHT2_12.png | K21: SH12.ISO | L21: 3000(2986,21) | M21: 1500(1492) | N21: INOX_FILM_AIR | O21: 8 | P21: 0.00:00:01 | Q21: 1 | R21: 92208 | S21: 28260 | T21: 26058 | U21: 1 | W21: 79 | X21: SB_0.8MM | Y21: 195VB001 | Z21: B | AA21: Bocna strana lijeva_sr | AB21: BENDS4 | AC21: 1 | AD21: 1 | AE21: 1 | AF21: 1 | AG21: 0.00:00:00 | AH21: 5058 | AI21: Multi Import Dxf | AJ21: N169535 | AK21: R4092056 | AL21: VOX-BRANKO | AM21: 6161 | AN21: ORMAR INOX | AP21: 25 od 78 | AQ21: 9 | AR21: Z:\005_Proizvodnja\004_Organizacija\Ledinski obrada TURA\PNG IKONE\9.png | AS21: 46112
D22: 16062025sb0_8mmReportTemplate.xml | E22: 55 | F22: C:\PrimaIndustrie\Maestro\Config\Resources\prima_power [320x200].png | G22: 16062025sb0_8mmReport | H22: PLTHS1530_YLS3000 | J22: C:\NTCam\data\Reports\Resources\Nestings\16062025sb0_8mm_SHT2_14.png | K22: SH14.ISO | L22: 3000(2992) | M22: 1500(1492) | N22: INOX_FILM_AIR | O22: 8 | P22: 0.00:00:01 | Q22: 1 | R22: 93360 | S22: 28260 | T22: 26384 | U22: 1 | W22: 89 | X22: SB_0.8MM | Y22: 195VB001 | Z22: B | AA22: Omega dna A | AB22: BENDS4 | AC22: 1 | AD22: 1 | AE22: 1 | AF22: 1 | AG22: 0.00:00:00 | AH22: 1269 | AI22: Multi Import Dxf | AJ22: N169535 | AK22: R4092050 | AL22: VOX-BRANKO | AM22: 6161 | AN22: ORMAR INOX | AP22: 26 od 78 | AQ22: 9 | AR22: Z:\005_Proizvodnja\004_Organizacija\Ledinski obrada TURA\PNG IKONE\9.png | AS22: 46112
... D84: 16062025sb0_8mmReportTemplate.xml | E84: 55 | F84: C:\PrimaIndustrie\Maestro\Config\Resources\prima_power [320x200].png | G84: 16062025sb0_8mmReport | H84: PLTHS1530_YLS3000 | J84: C:\NTCam\data\Reports\Resources\Nestings\16062025sb0_8mm_SHT2_40.png | K84: SH40.ISO | L84: 3000(2992) | M84: 1500(1492) | N84: INOX_FILM_AIR | O84: 8 | P84: 0.00:00:01 | Q84: 1 | R84: 81350 | S84: 28260 | T84: 22989 | U84: 1 | W84: 401 | X84: SB_0.8MM | Y84: 195VB002 | Z84: B | AA84: Omega police | AB84: BENDS4 | AC84: 1 | AD84: 2 | AE84: 1 | AF84: 1 | AG84: 0.00:00:00 | AH84: 856 | AI84: Multi Import Dxf | AJ84: N169536 | AK84: R4092120 | AL84: VOX-BRANKO | AM84: 6161 | AN84: ORMAR INOX | AP84: 26 od 26 | AQ84: 21 | AR84: Z:\005_Proizvodnja\004_Organizacija\Ledinski obrada TURA\PNG IKONE\21.png | AS84: 46112
D85: 16062025sb0_8mmReportTemplate.xml | E85: 55 | F85: C:\PrimaIndustrie\Maestro\Config\Resources\prima_power [320x200].png | G85: 16062025sb0_8mmReport | H85: PLTHS1530_YLS3000 | J85: C:\NTCam\data\Reports\Resources\Nestings\16062025sb0_8mm_SHT2_21.png | K85: SH21.ISO | L85: 3000(2992) | M85: 1500(1492) | N85: INOX_FILM_AIR | O85: 8 | P85: 0.00:00:01 | Q85: 1 | R85: 91504 | S85: 28260 | T85: 25859 | U85: 1 | W85: 148 | X85: SB_0.8MM | Y85: 225VB001 | AA85: Omega stalaze | AB85: BENDS4 | AC85: 5 | AD85: 5 | AE85: 1 | AF85: 1 | AG85: 0.00:00:00 | AH85: 518 | AI85: Multi Import Dxf | AJ85: N171213 | AK85: R4091742 | AL85: VOX-BRANKO | AM85: 2263 | AN85: POLICA SKLADIŠNA | AP85: 1 od 14 | AQ85: 36 | AR85: Z:\005_Proizvodnja\004_Organizacija\Ledinski obrada TURA\PNG IKONE\36.png | AS85: 46112
D86: 16062025sb0_8mmReportTemplate.xml | E86: 55 | F86: C:\PrimaIndustrie\Maestro\Config\Resources\prima_power [320x200].png | G86: 16062025sb0_8mmReport | H86: PLTHS1530_YLS3000 | J86: C:\NTCam\data\Reports\Resources\Nestings\16062025sb0_8mm_SHT2_29.png | K86: SH29.ISO | L86: 3000(2992) | M86: 1500(1492) | N86: INOX_FILM_AIR | O86: 8 | P86: 0.00:00:01 | Q86: 1 | R86: 91466 | S86: 28260 | T86: 25848 | U86: 1 | W86: 231 | X86: SB_0.8MM | Y86: 225VB001 | AA86: Omega stalaze | AB86: BENDS4 | AC86: 2 | AD86: 5 | AE86: 1 | AF86: 1 | AG86: 0.00:00:00 | AH86: 518 | AI86: Multi Import Dxf | AJ86: N171213 | AK86: R4091742 | AL86: VOX-BRANKO | AM86: 2263 | AN86: POLICA SKLADIŠNA | AP86: 2 od 14 | AQ86: 36 | AR86: Z:\005_Proizvodnja\004_Organizacija\Ledinski obrada TURA\PNG IKONE\36.png | AS86: 46112
D87: 16062025sb0_8mmReportTemplate.xml | E87: 55 | F87: C:\PrimaIndustrie\Maestro\Config\Resources\prima_power [320x200].png | G87: 16062025sb0_8mmReport | H87: PLTHS1530_YLS3000 | J87: C:\NTCam\data\Reports\Resources\Nestings\16062025sb0_8mm_SHT2_35.png | K87: SH35.ISO | L87: 3000(2992) | M87: 1500(1492) | N87: INOX_FILM_AIR | O87: 8 | P87: 0.00:00:01 | Q87: 1 | R87: 84688 | S87: 28260 | T87: 23933 | U87: 1 | W87: 301 | X87: SB_0.8MM | Y87: 225VB001 | AA87: Omega stalaze | AB87: BENDS4 | AC87: 1 | AD87: 5 | AE87: 1 | AF87: 1 | AG87: 0.00:00:00 | AH87: 518 | AI87: Multi Import Dxf | AJ87: N171213 | AK87: R4091742 | AL87: VOX-BRANKO | AM87: 2263 | AN87: POLICA SKLADIŠNA | AP87: 3 od 14 | AQ87: 36 | AR87: Z:\005_Proizvodnja\004_Organizacija\Ledinski obrada TURA\PNG IKONE\36.png | AS87: 46112
D88: 16062025sb0_8mmReportTemplate.xml | E88: 55 | F88: C:\PrimaIndustrie\Maestro\Config\Resources\prima_power [320x200].png | G88: 16062025sb0_8mmReport | H88: PLTHS1530_YLS3000 | J88: C:\NTCam\data\Reports\Resources\Nestings\16062025sb0_8mm_SHT2_36.png | K88: SH36.ISO | L88: 3000(2981,123) | M88: 1500(1490,8) | N88: INOX_FILM_AIR | O88: 8 | P88: 0.00:00:14 | Q88: 1 | R88: 83105 | S88: 28260 | T88: 23486 | U88: 1 | W88: 320 | X88: SB_0.8MM | Y88: 225VB001 | AA88: Omega stalaze | AB88: BENDS4 | AC88: 3 | AD88: 5 | AE88: 1 | AF88: 1 | AG88: 0.00:00:00 | AH88: 518 | AI88: Multi Import Dxf | AJ88: N171213 | AK88: R4091742 | AL88: VOX-BRANKO | AM88: 2263 | AN88: POLICA SKLADIŠNA | AP88: 4 od 14 | AQ88: 36 | AR88: Z:\005_Proizvodnja\004_Organizacija\Ledinski obrada TURA\PNG IKONE\36.png | AS88: 46112
D89: 16062025sb0_8mmReportTemplate.xml | E89: 55 | F89: C:\PrimaIndustrie\Maestro\Config\Resources\prima_power [320x200].png | G89: 16062025sb0_8mmReport | H89: PLTHS1530_YLS3000 | J89: C:\NTCam\data\Reports\Resources\Nestings\16062025sb0_8mm_SHT2_37.png | K89: SH37.ISO | L89: 3000(2919,813) | M89: 1500(1492) | N89: INOX_FILM_AIR | O89: 8 | P89: 0.00:00:27 | Q89: 1 | R89: 79806 | S89: 28260 | T89: 22553 | U89: 1 | W89: 329 | X89: SB_0.8MM | Y89: 225VB001 | AA89: Polica stalaze | AB89: BENDS4 | AC89: 2 | AD89: 5 | AE89: 1 | AF89: 9 | AG89: 0.00:00:00 | AH89: 1878 | AI89: Multi Import Dxf | AJ89: N171213 | AK89: R4091743 | AL89: VOX-BRANKO | AM89: 2263 | AN89: POLICA SKLADIŠNA | AP89: 5 od 14 | AQ89: 36 | AR89: Z:\005_Proizvodnja\004_Organizacija\Ledinski obrada TURA\PNG IKONE\36.png | AS89: 46112
D90: 16062025sb0_8mmReportTemplate.xml | E90: 55 | F90: C:\PrimaIndustrie\Maestro\Config\Resources\prima_power [320x200].png | G90: 16062025sb0_8mmReport | H90: PLTHS1530_YLS3000 | J90: C:\NTCam\data\Reports\Resources\Nestings\16062025sb0_8mm_SHT2_37.png | K90: SH37.ISO | L90: 3000(2919,813) | M90: 1500(1492) | N90: INOX_FILM_AIR | O90: 8 | P90: 0.00:00:27 | Q90: 1 | R90: 79806 | S90: 28260 | T90: 22553 | U90: 1 | W90: 330 | X90: SB_0.8MM | Y90: 225VB001 | AA90: Polica stalaze | AB90: BENDS4 | AC90: 1 | AD90: 5 | AE90: 1 | AF90: 9 | AG90: 0.00:00:00 | AH90: 1878 | AI90: Multi Import Dxf | AJ90: N171213 | AK90: R4091743 | AL90: VOX-BRANKO | AM90: 2263 | AN90: POLICA SKLADIŠNA | AP90: 6 od 14 | AQ90: 36 | AR90: Z:\005_Proizvodnja\004_Organizacija\Ledinski obrada TURA\PNG IKONE\36.png | AS90: 46112
D91: 16062025sb0_8mmReportTemplate.xml | E91: 55 | F91: C:\PrimaIndustrie\Maestro\Config\Resources\prima_power [320x200].png | G91: 16062025sb0_8mmReport | H91: PLTHS1530_YLS3000 | J91: C:\NTCam\data\Reports\Resources\Nestings\16062025sb0_8mm_SHT2_38.png | K91: SH38.ISO | L91: 3000(2990,698) | M91: 1500(1492) | N91: INOX_FILM_AIR | O91: 8 | P91: 0.00:00:20 | Q91: 1 | R91: 80090 | S91: 28260 | T91: 22634 | U91: 1 | W91: 336 | X91: SB_0.8MM | Y91: 225VB001 | AA91: Polica stalaze | AB91: BENDS4 | AC91: 5 | AD91: 5 | AE91: 1 | AF91: 9 | AG91: 0.00:00:00 | AH91: 1878 | AI91: Multi Import Dxf | AJ91: N171213 | AK91: R4091743 | AL91: VOX-BRANKO | AM91: 2263 | AN91: POLICA SKLADIŠNA | AP91: 7 od 14 | AQ91: 36 | AR91: Z:\005_Proizvodnja\004_Organizacija\Ledinski obrada TURA\PNG IKONE\36.png | AS91: 46112
D92: 16062025sb0_8mmReportTemplate.xml | E92: 55 | F92: C:\PrimaIndustrie\Maestro\Config\Resources\prima_power [320x200].png | G92: 16062025sb0_8mmReport | H92: PLTHS1530_YLS3000 | J92: C:\NTCam\data\Reports\Resources\Nestings\16062025sb0_8mm_SHT2_38.png | K92: SH38.ISO | L92: 3000(2990,698) | M92: 1500(1492) | N92: INOX_FILM_AIR | O92: 8 | P92: 0.00:00:20 | Q92: 1 | R92: 80090 | S92: 28260 | T92: 22634 | U92: 1 | W92: 338 | X92: SB_0.8MM | Y92: 225VB001 | AA92: Polica stalaze | AB92: BENDS4 | AC92: 3 | AD92: 5 | AE92: 1 | AF92: 9 | AG92: 0.00:00:00 | AH92: 1878 | AI92: Multi Import Dxf | AJ92: N171213 | AK92: R4091743 | AL92: VOX-BRANKO | AM92: 2263 | AN92: POLICA SKLADIŠNA | AP92: 8 od 14 | AQ92: 36 | AR92: Z:\005_Proizvodnja\004_Organizacija\Ledinski obrada TURA\PNG IKONE\36.png | AS92: 46112
D93: 16062025sb0_8mmReportTemplate.xml | E93: 55 | F93: C:\PrimaIndustrie\Maestro\Config\Resources\prima_power [320x200].png | G93: 16062025sb0_8mmReport | H93: PLTHS1530_YLS3000 | J93: C:\NTCam\data\Reports\Resources\Nestings\16062025sb0_8mm_SHT2_38.png | K93: SH38.ISO | L93: 3000(2990,698) | M93: 1500(1492) | N93: INOX_FILM_AIR | O93: 8 | P93: 0.00:00:20 | Q93: 1 | R93: 80090 | S93: 28260 | T93: 22634 | U93: 1 | W93: 351 | X93: SB_0.8MM | Y93: 225VB001 | AA93: Omega stalaze | AB93: BENDS4 | AC93: 4 | AD93: 5 | AE93: 1 | AF93: 1 | AG93: 0.00:00:00 | AH93: 518 | AI93: Multi Import Dxf | AJ93: N171213 | AK93: R4091742 | AL93: VOX-BRANKO | AM93: 2263 | AN93: POLICA SKLADIŠNA | AP93: 9 od 14 | AQ93: 36 | AR93: Z:\005_Proizvodnja\004_Organizacija\Ledinski obrada TURA\PNG IKONE\36.png | AS93: 46112
D94: 16062025sb0_8mmReportTemplate.xml | E94: 55 | F94: C:\PrimaIndustrie\Maestro\Config\Resources\prima_power [320x200].png | G94: 16062025sb0_8mmReport | H94: PLTHS1530_YLS3000 | J94: C:\NTCam\data\Reports\Resources\Nestings\16062025sb0_8mm_SHT2_41.png | K94: SH41.ISO | L94: 3000(1103) | M94: 1500(1492) | N94: INOX_FILM_AIR | O94: 8 | P94: 0.00:00:01 | Q94: 1 | R94: 27312 | S94: 28260 | T94: 7718 | U94: 1 | W94: 404 | X94: SB_0.8MM | Y94: 225VB001 | AA94: Polica stalaze | AB94: BENDS4 | AC94: 4 | AD94: 5 | AE94: 1 | AF94: 9 | AG94: 0.00:00:00 | AH94: 1878 | AI94: Multi Import Dxf | AJ94: N171213 | AK94: R4091743 | AL94: VOX-BRANKO | AM94: 2263 | AN94: POLICA SKLADIŠNA | AP94: 10 od 14 | AQ94: 36 | AR94: Z:\005_Proizvodnja\004_Organizacija\Ledinski obrada TURA\PNG IKONE\36.png | AS94: 46112
D95: 16062025sb0_8mmReportTemplate.xml | E95: 55 | F95: C:\PrimaIndustrie\Maestro\Config\Resources\prima_power [320x200].png | G95: 16062025sb0_8mmReport | H95: PLTHS1530_YLS3000 | J95: C:\NTCam\data\Reports\Resources\Nestings\16062025sb0_8mm_SHT2_14.png | K95: SH14.ISO | L95: 3000(2992) | M95: 1500(1492) | N95: INOX_FILM_AIR | O95: 8 | P95: 0.00:00:01 | Q95: 1 | R95: 93360 | S95: 28260 | T95: 26384 | U95: 1 | W95: 87 | X95: SB_0.8MM | Y95: 225VB002 | AA95: Polica stalaze | AB95: BENDS4 | AC95: 1 | AD95: 5 | AE95: 1 | AF95: 9 | AG95: 0.00:00:00 | AH95: 3933 | AI95: Multi Import Dxf | AJ95: N171214 | AK95: R4091750 | AL95: VOX-BRANKO | AM95: 2263 | AN95: POLICA SKLADIŠNA | AP95: 1 od 14 | AQ95: 27 | AR95: Z:\005_Proizvodnja\004_Organizacija\Ledinski obrada TURA\PNG IKONE\27.png | AS95: 46112
D96: 16062025sb0_8mmReportTemplate.xml | E96: 55 | F96: C:\PrimaIndustrie\Maestro\Config\Resources\prima_power [320x200].png | G96: 16062025sb0_8mmReport | H96: PLTHS1530_YLS3000 | J96: C:\NTCam\data\Reports\Resources\Nestings\16062025sb0_8mm_SHT2_25.png | K96: SH25.ISO | L96: 3000(2987,088) | M96: 1500(1492) | N96: INOX_FILM_AIR | O96: 8 | P96: 0.00:00:14 | Q96: 1 | R96: 89653 | S96: 28260 | T96: 25336 | U96: 1 | W96: 181 | X96: SB_0.8MM | Y96: 225VB002 | AA96: Polica stalaze | AB96: BENDS4 | AC96: 5 | AD96: 5 | AE96: 1 | AF96: 9 | AG96: 0.00:00:00 | AH96: 3933 | AI96: Multi Import Dxf | AJ96: N171214 | AK96: R4091750 | AL96: VOX-BRANKO | AM96: 2263 | AN96: POLICA SKLADIŠNA | AP96: 2 od 14 | AQ96: 27 | AR96: Z:\005_Proizvodnja\004_Organizacija\Ledinski obrada TURA\PNG IKONE\27.png | AS96: 46112
... D104: 16062025sb0_8mmReportTemplate.xml | E104: 55 | F104: C:\PrimaIndustrie\Maestro\Config\Resources\prima_power [320x200].png | G104: 16062025sb0_8mmReport | H104: PLTHS1530_YLS3000 | J104: C:\NTCam\data\Reports\Resources\Nestings\16062025sb0_8mm_SHT2_39.png | K104: SH39.ISO | L104: 3000(2983,62) | M104: 1500(1492) | N104: INOX_FILM_AIR | O104: 8 | P104: 0.00:00:01 | Q104: 1 | R104: 82937 | S104: 28260 | T104: 23438 | U104: 1 | W104: 365 | X104: SB_0.8MM | Y104: 225VB002 | AA104: Omega stalaze | AB104: BENDS4 | AC104: 3 | AD104: 5 | AE104: 1 | AF104: 1 | AG104: 0.00:00:00 | AH104: 1105 | AI104: Multi Import Dxf | AJ104: N171214 | AK104: R4091749 | AL104: VOX-BRANKO | AM104: 2263 | AN104: POLICA SKLADIŠNA | AP104: 10 od 14 | AQ104: 27 | AR104: Z:\005_Proizvodnja\004_Organizacija\Ledinski obrada TURA\PNG IKONE\27.png | AS104: 46112
AT156: -16062025sb1_5mm_SH2.ISO
AT277: -16062025sb1_5mm_SH2.ISO
AT382: -16062025sb1_5mm_SH2.ISO
